Workbook

Sheet Location Impute Tables
A1: IsFraud | B1: 1
A3: Count of MerchantCategory | B3: Column Labels
A4: Row Labels | B4: Chicago | C4: Houston | D4: Los Angeles | E4: Miami | F4: New York | G4: (blank) | H4: max | I4: num occurrances
A5: Clothing | B5: 1 | C5: 1 | D5: 1 | E5: 1 | F5: 2 | G5: 0 | H5: =MAX(B5:F5) -> 2 | I5: =COUNTIF(B5:F5,"="&H5) -> 1 | J5: =IF(I5>1,VLOOKUP(A5,$A$15:$I$19,9),INDEX($B$4:$F$4,1,MATCH(H5,B5:F5,0))) -> New York
A6: Electronics | B6: 1 | C6: 1 | D6: 1 | E6: 1 | F6: 0 | G6: 0 | H6: =MAX(B6:F6) -> 1 | I6: =COUNTIF(B6:F6,"="&H6) -> 4 | J6: =IF(I6>1,VLOOKUP(A6,$A$15:$I$19,9),INDEX($B$4:$F$4,1,MATCH(H6,B6:F6,0))) -> Los Angeles
A7: Entertainment | B7: 1 | C7: 1 | D7: 1 | E7: 1 | F7: 1 | G7: 0 | H7: =MAX(B7:F7) -> 1 | I7: =COUNTIF(B7:F7,"="&H7) -> 5 | J7: =IF(I7>1,VLOOKUP(A7,$A$15:$I$19,9),INDEX($B$4:$F$4,1,MATCH(H7,B7:F7,0))) -> New York
A8: Groceries | B8: 1 | C8: 0 | D8: 1 | E8: 2 | F8: 3 | G8: 1 | H8: =MAX(B8:F8) -> 3 | I8: =COUNTIF(B8:F8,"="&H8) -> 1 | J8: =IF(I8>1,VLOOKUP(A8,$A$15:$I$19,9),INDEX($B$4:$F$4,1,MATCH(H8,B8:F8,0))) -> New York
A9: Travel | B9: 1 | C9: 0 | D9: 1 | E9: 2 | F9: 0 | G9: 0 | H9: =MAX(B9:F9) -> 2 | I9: =COUNTIF(B9:F9,"="&H9) -> 1 | J9: =IF(I9>1,VLOOKUP(A9,$A$15:$I$19,9),INDEX($B$4:$F$4,1,MATCH(H9,B9:F9,0))) -> Miami
A11: IsFraud | B11: 1
A13: Average of Amount | B13: Column Labels
A14: Row Labels | B14: Chicago | C14: Houston | D14: Los Angeles | E14: Miami | F14: New York | G14: (blank) | H14: max
A15: Clothing | B15: 216.61 | C15: 371.27 | D15: 539.8 | E15: 162.47 | F15: 360.83 | G15: 0.0 | H15: =MAX(B15:F15) -> 539.8 | I15: =INDEX($B$14:$F$14,1,MATCH(H15,B15:F15,0)) -> Los Angeles
A16: Electronics | B16: 514.72 | C16: 860.87 | D16: 974.42 | E16: 312.4 | F16: 0.0 | G16: 0.0 | H16: =MAX(B16:F16) -> 974.42 | I16: =INDEX($B$14:$F$14,1,MATCH(H16,B16:F16,0)) -> Los Angeles
A17: Entertainment | B17: 31.47 | C17: 185.67 | D17: 714.88 | E17: 586.19 | F17: 939.56 | G17: 0.0 | H17: =MAX(B17:F17) -> 939.56 | I17: =INDEX($B$14:$F$14,1,MATCH(H17,B17:F17,0)) -> New York
A18: Groceries | B18: 52.43 | C18: 0.0 | D18: 94.58 | E18: 756.92 | F18: 357.01333 | G18: 663.84 | H18: =MAX(B18:F18) -> 756.92 | I18: =INDEX($B$14:$F$14,1,MATCH(H18,B18:F18,0)) -> Miami
A19: Travel | B19: 892.15 | C19: 0.0 | D19: 98.08 | E19: 225.05 | F19: 0.0 | G19: 0.0 | H19: =MAX(B19:F19) -> 892.15 | I19: =INDEX($B$14:$F$14,1,MATCH(H19,B19:F19,0)) -> Chicago
A21: IsFraud | B21: 0
A23: Count of Location | B23: Column Labels
A24: Row Labels | B24: Chicago | C24: Houston | D24: Los Angeles | E24: Miami | F24: New York | G24: (blank) | H24: max | I24: num occurrances
A25: Clothing | B25: 16 | C25: 10 | D25: 11 | E25: 16 | F25: 16 | H25: =MAX(B25:F25) -> 16 | I25: =COUNTIF(B25:F25,"="&H25) -> 3 | J25: =IF(I25>1,VLOOKUP(A25,$A$35:$I$39,9,0),INDEX($B$24:$F$24,1,MATCH(H25,B25:F25,0))) -> Chicago
A26: Electronics | B26: 17 | C26: 17 | D26: 20 | E26: 25 | F26: 19 | H26: =MAX(B26:F26) -> 25 | I26: =COUNTIF(B26:F26,"="&H26) -> 1 | J26: =IF(I26>1,VLOOKUP(A26,$A$35:$I$39,9,0),INDEX($B$24:$F$24,1,MATCH(H26,B26:F26,0))) -> Miami
A27: Entertainment | B27: 24 | C27: 11 | D27: 25 | E27: 19 | F27: 19 | H27: =MAX(B27:F27) -> 25 | I27: =COUNTIF(B27:F27,"="&H27) -> 1 | J27: =IF(I27>1,VLOOKUP(A27,$A$35:$I$39,9,0),INDEX($B$24:$F$24,1,MATCH(H27,B27:F27,0))) -> Los Angeles
A28: Groceries | B28: 22 | C28: 15 | D28: 13 | E28: 23 | F28: 21 | H28: =MAX(B28:F28) -> 23 | I28: =COUNTIF(B28:F28,"="&H28) -> 1 | J28: =IF(I28>1,VLOOKUP(A28,$A$35:$I$39,9,0),INDEX($B$24:$F$24,1,MATCH(H28,B28:F28,0))) -> Miami
A29: Travel | B29: 20 | C29: 24 | D29: 23 | E29: 14 | F29: 9 | H29: =MAX(B29:F29) -> 24 | I29: =COUNTIF(B29:F29,"="&H29) -> 1 | J29: =IF(I29>1,VLOOKUP(A29,$A$35:$I$39,9,0),INDEX($B$24:$F$24,1,MATCH(H29,B29:F29,0))) -> Houston
A31: IsFraud | B31: 0
A33: Average of Amount | B33: Column Labels
A34: Row Labels | B34: Chicago | C34: Houston | D34: Los Angeles | E34: Miami | F34: New York | G34: (blank) | H34: max
A35: Clothing | B35: 1389.8869 | C35: 1230.3233 | D35: 535.274 | E35: 536.42063 | F35: 426.96563 | G35: 699.165 | H35: =MAX(B35:F35) -> 1389.8869 | I35: =INDEX($B$34:$F$34,1,MATCH(H35,B35:F35,0)) -> Chicago
A36: Electronics | B36: 486.12 | C36: 344.73067 | D36: 477.34 | E36: 964.82385 | F36: 842.45207 | G36: 761.75 | H36: =MAX(B36:F36) -> 964.82385 | I36: =INDEX($B$34:$F$34,1,MATCH(H36,B36:F36,0)) -> Miami
A37: Entertainment | B37: 437.8025 | C37: 1616.6689 | D37: 553.32783 | E37: 558.25737 | F37: 904.33649 | G37: 456.70833 | H37: =MAX(B37:F37) -> 1616.6689 | I37: =INDEX($B$34:$F$34,1,MATCH(H37,B37:F37,0)) -> Houston
A38: Groceries | B38: 463.837 | C38: 510.41857 | D38: 490.4725 | E38: 834.76579 | F38: 372.6081 | G38: 435.66875 | H38: =MAX(B38:F38) -> 834.76579 | I38: =INDEX($B$34:$F$34,1,MATCH(H38,B38:F38,0)) -> Miami
A39: Travel | B39: 585.44833 | C39: 467.32913 | D39: 557.75364 | E39: 886.90909 | F39: 736.75222 | G39: 493.042 | H39: =MAX(B39:F39) -> 886.90909 | I39: =INDEX($B$34:$F$34,1,MATCH(H39,B39:F39,0)) -> Miami

Sheet Amount Impute Table
A1: IsFraud | B1: 1
A3: Average of Amount | B3: Column Labels
A4: Row Labels | B4: Clothing | C4: Electronics | D4: Entertainment | E4: Groceries | F4: Travel
A5: Chicago | B5: 216.61 | C5: 514.72 | D5: 31.47 | E5: 52.43 | F5: 892.15
A6: Houston | B6: 371.27 | C6: 860.87 | D6: 185.67
A7: Los Angeles | B7: 539.8 | C7: 974.42 | D7: 714.88 | E7: 94.58 | F7: 98.08
A8: Miami | B8: 162.47 | C8: 312.4 | D8: 586.19 | E8: 756.92 | F8: 225.05
A9: New York | B9: 360.83 | D9: 939.56 | E9: 433.72
A12: IsFraud | B12: 0
A14: Average of Amount | B14: Column Labels
A15: Row Labels | B15: Clothing | C15: Electronics | D15: Entertainment | E15: Groceries | F15: Travel
A16: Chicago | B16: 1308.6255 | C16: 486.12 | D16: 437.8025 | E16: 463.837 | F16: 585.44833
A17: Houston | B17: 1230.3233 | C17: 344.73067 | D17: 1616.6689 | E17: 510.41857 | F17: 471.92071
A18: Los Angeles | B18: 535.274 | C18: 477.34 | D18: 533.33759 | E18: 490.4725 | F18: 557.75364
A19: Miami | B19: 536.42063 | C19: 956.36244 | D19: 558.25737 | E19: 724.67005 | F19: 886.90909
A20: New York | B20: 426.96563 | C20: 842.45207 | D20: 904.33649 | E20: 372.6081 | F20: 736.75222

Sheet fraud_data
A1: TransactionID | B1: Amount | C1: Time | D1: Location | E1: MerchantCategory | F1: CardHolderAge | G1: IsFraud | H1: Location imputed | I1: Amount Imputed
A2: 500 | B2: 986.22 | C2: 81974 | D2: Chicago | E2: Electronics | F2: 37 | G2: 0 | H2: =IF(ISBLANK(D2),IF(G2=1,VLOOKUP(E2,'Location Impute Tables'!$A$5:$J$9,10,0),VLOOKUP(E2,'Location Impute Tables'!$A$25:$J$29,10,0)),D2) -> Chicago | I2: =IF(ISBLANK(B2),IF(G2=1,VLOOKUP(H2,'Amount Impute Table'!$A$5:$F$9,MATCH(fraud_data!E2,'Amount Impute Table'!$B$4:$F$4,0)+1,FALSE),VLOOKUP(H2,'Amount Impute Table'!$A$16:$F$20,MATCH(E2,'Amount Impute Table'!$B$15:$F$15,0)+1,0)),B2) -> 986.22
A3: 499 | B3: 974.42 | C3: 52603 | D3: Los Angeles | E3: Electronics | F3: 21 | G3: 1 | H3: =IF(ISBLANK(D3),IF(G3=1,VLOOKUP(E3,'Location Impute Tables'!$A$5:$J$9,10,0),VLOOKUP(E3,'Location Impute Tables'!$A$25:$J$29,10,0)),D3) -> Los Angeles | I3: =IF(ISBLANK(B3),IF(G3=1,VLOOKUP(H3,'Amount Impute Table'!$A$5:$F$9,MATCH(fraud_data!E3,'Amount Impute Table'!$B$4:$F$4,0)+1,FALSE),VLOOKUP(H3,'Amount Impute Table'!$A$16:$F$20,MATCH(E3,'Amount Impute Table'!$B$15:$F$15,0)+1,0)),B3) -> 974.42
A4: 498 | B4: 78.66 | C4: 75629 | D4: Miami | E4: Clothing | F4: 78 | G4: 0 | H4: =IF(ISBLANK(D4),IF(G4=1,VLOOKUP(E4,'Location Impute Tables'!$A$5:$J$9,10,0),VLOOKUP(E4,'Location Impute Tables'!$A$25:$J$29,10,0)),D4) -> Miami | I4: =IF(ISBLANK(B4),IF(G4=1,VLOOKUP(H4,'Amount Impute Table'!$A$5:$F$9,MATCH(fraud_data!E4,'Amount Impute Table'!$B$4:$F$4,0)+1,FALSE),VLOOKUP(H4,'Amount Impute Table'!$A$16:$F$20,MATCH(E4,'Amount Impute Table'!$B$15:$F$15,0)+1,0)),B4) -> 78.66
A5: 497 | B5: 584.07 | C5: 78623 | D5: Miami | E5: Groceries | F5: 64 | G5: 1 | H5: =IF(ISBLANK(D5),IF(G5=1,VLOOKUP(E5,'Location Impute Tables'!$A$5:$J$9,10,0),VLOOKUP(E5,'Location Impute Tables'!$A$25:$J$29,10,0)),D5) -> Miami | I5: =IF(ISBLANK(B5),IF(G5=1,VLOOKUP(H5,'Amount Impute Table'!$A$5:$F$9,MATCH(fraud_data!E5,'Amount Impute Table'!$B$4:$F$4,0)+1,FALSE),VLOOKUP(H5,'Amount Impute Table'!$A$16:$F$20,MATCH(E5,'Amount Impute Table'!$B$15:$F$15,0)+1,0)),B5) -> 584.07
A6: 496 | B6: 354 | C6: 48770 | D6: Houston | E6: Travel | F6: 21 | G6: 0 | H6: =IF(ISBLANK(D6),IF(G6=1,VLOOKUP(E6,'Location Impute Tables'!$A$5:$J$9,10,0),VLOOKUP(E6,'Location Impute Tables'!$A$25:$J$29,10,0)),D6) -> Houston | I6: =IF(ISBLANK(B6),IF(G6=1,VLOOKUP(H6,'Amount Impute Table'!$A$5:$F$9,MATCH(fraud_data!E6,'Amount Impute Table'!$B$4:$F$4,0)+1,FALSE),VLOOKUP(H6,'Amount Impute Table'!$A$16:$F$20,MATCH(E6,'Amount Impute Table'!$B$15:$F$15,0)+1,0)),B6) -> 354
A7: 495 | B7: 464.23 | C7: 40806 | D7: New York | E7: Electronics | F7: 75 | G7: 0 | H7: =IF(ISBLANK(D7),IF(G7=1,VLOOKUP(E7,'Location Impute Tables'!$A$5:$J$9,10,0),VLOOKUP(E7,'Location Impute Tables'!$A$25:$J$29,10,0)),D7) -> New York | I7: =IF(ISBLANK(B7),IF(G7=1,VLOOKUP(H7,'Amount Impute Table'!$A$5:$F$9,MATCH(fraud_data!E7,'Amount Impute Table'!$B$4:$F$4,0)+1,FALSE),VLOOKUP(H7,'Amount Impute Table'!$A$16:$F$20,MATCH(E7,'Amount Impute Table'!$B$15:$F$15,0)+1,0)),B7) -> 464.23
A8: 494 | B8: 188.93 | C8: 12342 | D8: New York | E8: Groceries | F8: 54 | G8: 0 | H8: =IF(ISBLANK(D8),IF(G8=1,VLOOKUP(E8,'Location Impute Tables'!$A$5:$J$9,10,0),VLOOKUP(E8,'Location Impute Tables'!$A$25:$J$29,10,0)),D8) -> New York | I8: =IF(ISBLANK(B8),IF(G8=1,VLOOKUP(H8,'Amount Impute Table'!$A$5:$F$9,MATCH(fraud_data!E8,'Amount Impute Table'!$B$4:$F$4,0)+1,FALSE),VLOOKUP(H8,'Amount Impute Table'!$A$16:$F$20,MATCH(E8,'Amount Impute Table'!$B$15:$F$15,0)+1,0)),B8) -> 188.93
A9: 493 | B9: 278.1 | C9: 52487 | D9: Houston | E9: Travel | F9: 36 | G9: 0 | H9: =IF(ISBLANK(D9),IF(G9=1,VLOOKUP(E9,'Location Impute Tables'!$A$5:$J$9,10,0),VLOOKUP(E9,'Location Impute Tables'!$A$25:$J$29,10,0)),D9) -> Houston | I9: =IF(ISBLANK(B9),IF(G9=1,VLOOKUP(H9,'Amount Impute Table'!$A$5:$F$9,MATCH(fraud_data!E9,'Amount Impute Table'!$B$4:$F$4,0)+1,FALSE),VLOOKUP(H9,'Amount Impute Table'!$A$16:$F$20,MATCH(E9,'Amount Impute Table'!$B$15:$F$15,0)+1,0)),B9) -> 278.1
A10: 492 | B10: 620.51 | C10: 55168 | D10: Houston | E10: Groceries | F10: 73 | G10: 0 | H10: =IF(ISBLANK(D10),IF(G10=1,VLOOKUP(E10,'Location Impute Tables'!$A$5:$J$9,10,0),VLOOKUP(E10,'Location Impute Tables'!$A$25:$J$29,10,0)),D10) -> Houston | I10: =IF(ISBLANK(B10),IF(G10=1,VLOOKUP(H10,'Amount Impute Table'!$A$5:$F$9,MATCH(fraud_data!E10,'Amount Impute Table'!$B$4:$F$4,0)+1,FALSE),VLOOKUP(H10,'Amount Impute Table'!$A$16:$F$20,MATCH(E10,'Amount Impute Table'!$B$15:$F$15,0)+1,0)),B10) -> 620.51
A11: 491 | B11: 456.2 | C11: 65155 | D11: Houston | E11: Electronics | F11: 23 | G11: 0 | H11: =IF(ISBLANK(D11),IF(G11=1,VLOOKUP(E11,'Location Impute Tables'!$A$5:$J$9,10,0),VLOOKUP(E11,'Location Impute Tables'!$A$25:$J$29,10,0)),D11) -> Houston | I11: =IF(ISBLANK(B11),IF(G11=1,VLOOKUP(H11,'Amount Impute Table'!$A$5:$F$9,MATCH(fraud_data!E11,'Amount Impute Table'!$B$4:$F$4,0)+1,FALSE),VLOOKUP(H11,'Amount Impute Table'!$A$16:$F$20,MATCH(E11,'Amount Impute Table'!$B$15:$F$15,0)+1,0)),B11) -> 456.2
A12: 490 | B12: 890.37 | C12: 25522 | D12: New York | E12: Entertainment | G12: 0 | H12: =IF(ISBLANK(D12),IF(G12=1,VLOOKUP(E12,'Location Impute Tables'!$A$5:$J$9,10,0),VLOOKUP(E12,'Location Impute Tables'!$A$25:$J$29,10,0)),D12) -> New York | I12: =IF(ISBLANK(B12),IF(G12=1,VLOOKUP(H12,'Amount Impute Table'!$A$5:$F$9,MATCH(fraud_data!E12,'Amount Impute Table'!$B$4:$F$4,0)+1,FALSE),VLOOKUP(H12,'Amount Impute Table'!$A$16:$F$20,MATCH(E12,'Amount Impute Table'!$B$15:$F$15,0)+1,0)),B12) -> 890.37
A13: 489 | B13: 950.46 | C13: 38565 | D13: New York | E13: Travel | F13: 48 | G13: 0 | H13: =IF(ISBLANK(D13),IF(G13=1,VLOOKUP(E13,'Location Impute Tables'!$A$5:$J$9,10,0),VLOOKUP(E13,'Location Impute Tables'!$A$25:$J$29,10,0)),D13) -> New York | I13: =IF(ISBLANK(B13),IF(G13=1,VLOOKUP(H13,'Amount Impute Table'!$A$5:$F$9,MATCH(fraud_data!E13,'Amount Impute Table'!$B$4:$F$4,0)+1,FALSE),VLOOKUP(H13,'Amount Impute Table'!$A$16:$F$20,MATCH(E13,'Amount Impute Table'!$B$15:$F$15,0)+1,0)),B13) -> 950.46
A14: 488 | B14: 281.68 | C14: 11485 | D14: Houston | E14: Groceries | F14: 68 | G14: 0 | H14: =IF(ISBLANK(D14),IF(G14=1,VLOOKUP(E14,'Location Impute Tables'!$A$5:$J$9,10,0),VLOOKUP(E14,'Location Impute Tables'!$A$25:$J$29,10,0)),D14) -> Houston | I14: =IF(ISBLANK(B14),IF(G14=1,VLOOKUP(H14,'Amount Impute Table'!$A$5:$F$9,MATCH(fraud_data!E14,'Amount Impute Table'!$B$4:$F$4,0)+1,FALSE),VLOOKUP(H14,'Amount Impute Table'!$A$16:$F$20,MATCH(E14,'Amount Impute Table'!$B$15:$F$15,0)+1,0)),B14) -> 281.68
A15: 487 | B15: 46.4 | C15: 26737 | D15: Chicago | E15: Entertainment | F15: 33 | G15: 0 | H15: =IF(ISBLANK(D15),IF(G15=1,VLOOKUP(E15,'Location Impute Tables'!$A$5:$J$9,10,0),VLOOKUP(E15,'Location Impute Tables'!$A$25:$J$29,10,0)),D15) -> Chicago | I15: =IF(ISBLANK(B15),IF(G15=1,VLOOKUP(H15,'Amount Impute Table'!$A$5:$F$9,MATCH(fraud_data!E15,'Amount Impute Table'!$B$4:$F$4,0)+1,FALSE),VLOOKUP(H15,'Amount Impute Table'!$A$16:$F$20,MATCH(E15,'Amount Impute Table'!$B$15:$F$15,0)+1,0)),B15) -> 46.4
A16: 486 | B16: 901.26 | C16: 38000 | D16: Los Angeles | E16: Entertainment | F16: 28 | G16: 0 | H16: =IF(ISBLANK(D16),IF(G16=1,VLOOKUP(E16,'Location Impute Tables'!$A$5:$J$9,10,0),VLOOKUP(E16,'Location Impute Tables'!$A$25:$J$29,10,0)),D16) -> Los Angeles | I16: =IF(ISBLANK(B16),IF(G16=1,VLOOKUP(H16,'Amount Impute Table'!$A$5:$F$9,MATCH(fraud_data!E16,'Amount Impute Table'!$B$4:$F$4,0)+1,FALSE),VLOOKUP(H16,'Amount Impute Table'!$A$16:$F$20,MATCH(E16,'Amount Impute Table'!$B$15:$F$15,0)+1,0)),B16) -> 901.26
A17: 485 | C17: 6645 | D17: Houston | E17: Travel | F17: 37 | G17: 0 | H17: =IF(ISBLANK(D17),IF(G17=1,VLOOKUP(E17,'Location Impute Tables'!$A$5:$J$9,10,0),VLOOKUP(E17,'Location Impute Tables'!$A$25:$J$29,10,0)),D17) -> Houston | I17: =IF(ISBLANK(B17),IF(G17=1,VLOOKUP(H17,'Amount Impute Table'!$A$5:$F$9,MATCH(fraud_data!E17,'Amount Impute Table'!$B$4:$F$4,0)+1,FALSE),VLOOKUP(H17,'Amount Impute Table'!$A$16:$F$20,MATCH(E17,'Amount Impute Table'!$B$15:$F$15,0)+1,0)),B17) -> 471.92071
A18: 484 | B18: 627.93 | C18: 28865 | D18: Miami | E18: Electronics | F18: 74 | G18: 0 | H18: =IF(ISBLANK(D18),IF(G18=1,VLOOKUP(E18,'Location Impute Tables'!$A$5:$J$9,10,0),VLOOKUP(E18,'Location Impute Tables'!$A$25:$J$29,10,0)),D18) -> Miami | I18: =IF(ISBLANK(B18),IF(G18=1,VLOOKUP(H18,'Amount Impute Table'!$A$5:$F$9,MATCH(fraud_data!E18,'Amount Impute Table'!$B$4:$F$4,0)+1,FALSE),VLOOKUP(H18,'Amount Impute Table'!$A$16:$F$20,MATCH(E18,'Amount Impute Table'!$B$15:$F$15,0)+1,0)),B18) -> 627.93
A19: 483 | B19: 455.09 | C19: 48302 | D19: Houston | E19: Groceries | F19: 70 | G19: 0 | H19: =IF(ISBLANK(D19),IF(G19=1,VLOOKUP(E19,'Location Impute Tables'!$A$5:$J$9,10,0),VLOOKUP(E19,'Location Impute Tables'!$A$25:$J$29,10,0)),D19) -> Houston | I19: =IF(ISBLANK(B19),IF(G19=1,VLOOKUP(H19,'Amount Impute Table'!$A$5:$F$9,MATCH(fraud_data!E19,'Amount Impute Table'!$B$4:$F$4,0)+1,FALSE),VLOOKUP(H19,'Amount Impute Table'!$A$16:$F$20,MATCH(E19,'Amount Impute Table'!$B$15:$F$15,0)+1,0)),B19) -> 455.09
A20: 482 | B20: 696.05 | C20: 38258 | D20: Miami | E20: Entertainment | F20: 51 | G20: 0 | H20: =IF(ISBLANK(D20),IF(G20=1,VLOOKUP(E20,'Location Impute Tables'!$A$5:$J$9,10,0),VLOOKUP(E20,'Location Impute Tables'!$A$25:$J$29,10,0)),D20) -> Miami | I20: =IF(ISBLANK(B20),IF(G20=1,VLOOKUP(H20,'Amount Impute Table'!$A$5:$F$9,MATCH(fraud_data!E20,'Amount Impute Table'!$B$4:$F$4,0)+1,FALSE),VLOOKUP(H20,'Amount Impute Table'!$A$16:$F$20,MATCH(E20,'Amount Impute Table'!$B$15:$F$15,0)+1,0)),B20) -> 696.05
A21: 481 | B21: 629.77 | C21: 64077 | D21: Chicago | E21: Travel | F21: 74 | G21: 0 | H21: =IF(ISBLANK(D21),IF(G21=1,VLOOKUP(E21,'Location Impute Tables'!$A$5:$J$9,10,0),VLOOKUP(E21,'Location Impute Tables'!$A$25:$J$29,10,0)),D21) -> Chicago | I21: =IF(ISBLANK(B21),IF(G21=1,VLOOKUP(H21,'Amount Impute Table'!$A$5:$F$9,MATCH(fraud_data!E21,'Amount Impute Table'!$B$4:$F$4,0)+1,FALSE),VLOOKUP(H21,'Amount Impute Table'!$A$16:$F$20,MATCH(E21,'Amount Impute Table'!$B$15:$F$15,0)+1,0)),B21) -> 629.77
A22: 480 | B22: 523.57 | C22: 33536 | D22: Houston | E22: Electronics | F22: 31 | G22: 0 | H22: =IF(ISBLANK(D22),IF(G22=1,VLOOKUP(E22,'Location Impute Tables'!$A$5:$J$9,10,0),VLOOKUP(E22,'Location Impute Tables'!$A$25:$J$29,10,0)),D22) -> Houston | I22: =IF(ISBLANK(B22),IF(G22=1,VLOOKUP(H22,'Amount Impute Table'!$A$5:$F$9,MATCH(fraud_data!E22,'Amount Impute Table'!$B$4:$F$4,0)+1,FALSE),VLOOKUP(H22,'Amount Impute Table'!$A$16:$F$20,MATCH(E22,'Amount Impute Table'!$B$15:$F$15,0)+1,0)),B22) -> 523.57
A23: 479 | B23: 969.33 | C23: 18449 | D23: Los Angeles | E23: Electronics | F23: 31 | G23: 0 | H23: =IF(ISBLANK(D23),IF(G23=1,VLOOKUP(E23,'Location Impute Tables'!$A$5:$J$9,10,0),VLOOKUP(E23,'Location Impute Tables'!$A$25:$J$29,10,0)),D23) -> Los Angeles | I23: =IF(ISBLANK(B23),IF(G23=1,VLOOKUP(H23,'Amount Impute Table'!$A$5:$F$9,MATCH(fraud_data!E23,'Amount Impute Table'!$B$4:$F$4,0)+1,FALSE),VLOOKUP(H23,'Amount Impute Table'!$A$16:$F$20,MATCH(E23,'Amount Impute Table'!$B$15:$F$15,0)+1,0)),B23) -> 969.33
A24: 478 | B24: 554.3 | C24: 72847 | D24: Chicago | E24: Entertainment | F24: 34 | G24: 0 | H24: =IF(ISBLANK(D24),IF(G24=1,VLOOKUP(E24,'Location Impute Tables'!$A$5:$J$9,10,0),VLOOKUP(E24,'Location Impute Tables'!$A$25:$J$29,10,0)),D24) -> Chicago | I24: =IF(ISBLANK(B24),IF(G24=1,VLOOKUP(H24,'Amount Impute Table'!$A$5:$F$9,MATCH(fraud_data!E24,'Amount Impute Table'!$B$4:$F$4,0)+1,FALSE),VLOOKUP(H24,'Amount Impute Table'!$A$16:$F$20,MATCH(E24,'Amount Impute Table'!$B$15:$F$15,0)+1,0)),B24) -> 554.3
A25: 477 | B25: 74.72 | C25: 42460 | D25: Miami | E25: Entertainment | F25: 29 | G25: 0 | H25: =IF(ISBLANK(D25),IF(G25=1,VLOOKUP(E25,'Location Impute Tables'!$A$5:$J$9,10,0),VLOOKUP(E25,'Location Impute Tables'!$A$25:$J$29,10,0)),D25) -> Miami | I25: =IF(ISBLANK(B25),IF(G25=1,VLOOKUP(H25,'Amount Impute Table'!$A$5:$F$9,MATCH(fraud_data!E25,'Amount Impute Table'!$B$4:$F$4,0)+1,FALSE),VLOOKUP(H25,'Amount Impute Table'!$A$16:$F$20,MATCH(E25,'Amount Impute Table'!$B$15:$F$15,0)+1,0)),B25) -> 74.72
A26: 476 | B26: 992.97 | C26: 27952 | D26: Miami | E26: Travel | F26: 71 | G26: 0 | H26: =IF(ISBLANK(D26),IF(G26=1,VLOOKUP(E26,'Location Impute Tables'!$A$5:$J$9,10,0),VLOOKUP(E26,'Location Impute Tables'!$A$25:$J$29,10,0)),D26) -> Miami | I26: =IF(ISBLANK(B26),IF(G26=1,VLOOKUP(H26,'Amount Impute Table'!$A$5:$F$9,MATCH(fraud_data!E26,'Amount Impute Table'!$B$4:$F$4,0)+1,FALSE),VLOOKUP(H26,'Amount Impute Table'!$A$16:$F$20,MATCH(E26,'Amount Impute Table'!$B$15:$F$15,0)+1,0)),B26) -> 992.97
A27: 475 | B27: 528.17 | C27: 59676 | D27: New York | E27: Clothing | F27: 75 | G27: 0 | H27: =IF(ISBLANK(D27),IF(G27=1,VLOOKUP(E27,'Location Impute Tables'!$A$5:$J$9,10,0),VLOOKUP(E27,'Location Impute Tables'!$A$25:$J$29,10,0)),D27) -> New York | I27: =IF(ISBLANK(B27),IF(G27=1,VLOOKUP(H27,'Amount Impute Table'!$A$5:$F$9,MATCH(fraud_data!E27,'Amount Impute Table'!$B$4:$F$4,0)+1,FALSE),VLOOKUP(H27,'Amount Impute Table'!$A$16:$F$20,MATCH(E27,'Amount Impute Table'!$B$15:$F$15,0)+1,0)),B27) -> 528.17
A28: 474 | B28: 891.25 | C28: 2717 | D28: New York | E28: Entertainment | F28: 43 | G28: 0 | H28: =IF(ISBLANK(D28),IF(G28=1,VLOOKUP(E28,'Location Impute Tables'!$A$5:$J$9,10,0),VLOOKUP(E28,'Location Impute Tables'!$A$25:$J$29,10,0)),D28) -> New York | I28: =IF(ISBLANK(B28),IF(G28=1,VLOOKUP(H28,'Amount Impute Table'!$A$5:$F$9,MATCH(fraud_data!E28,'Amount Impute Table'!$B$4:$F$4,0)+1,FALSE),VLOOKUP(H28,'Amount Impute Table'!$A$16:$F$20,MATCH(E28,'Amount Impute Table'!$B$15:$F$15,0)+1,0)),B28) -> 891.25
A29: 473 | B29: 44.12 | C29: 2079 | D29: Houston | E29: Travel | F29: 59 | G29: 0 | H29: =IF(ISBLANK(D29),IF(G29=1,VLOOKUP(E29,'Location Impute Tables'!$A$5:$J$9,10,0),VLOOKUP(E29,'Location Impute Tables'!$A$25:$J$29,10,0)),D29) -> Houston | I29: =IF(ISBLANK(B29),IF(G29=1,VLOOKUP(H29,'Amount Impute Table'!$A$5:$F$9,MATCH(fraud_data!E29,'Amount Impute Table'!$B$4:$F$4,0)+1,FALSE),VLOOKUP(H29,'Amount Impute Table'!$A$16:$F$20,MATCH(E29,'Amount Impute Table'!$B$15:$F$15,0)+1,0)),B29) -> 44.12
... A33: 469 | B33: 224.37 | C33: 2482 | D33: Houston | E33: Electronics | F33: 26 | G33: 0 | H33: =IF(ISBLANK(D33),IF(G33=1,VLOOKUP(E33,'Location Impute Tables'!$A$5:$J$9,10,0),VLOOKUP(E33,'Location Impute Tables'!$A$25:$J$29,10,0)),D33) -> Houston | I33: =IF(ISBLANK(B33),IF(G33=1,VLOOKUP(H33,'Amount Impute Table'!$A$5:$F$9,MATCH(fraud_data!E33,'Amount Impute Table'!$B$4:$F$4,0)+1,FALSE),VLOOKUP(H33,'Amount Impute Table'!$A$16:$F$20,MATCH(E33,'Amount Impute Table'!$B$15:$F$15,0)+1,0)),B33) -> 224.37
A34: 468 | C34: 41949 | D34: New York | E34: Entertainment | F34: 30 | G34: 0 | H34: =IF(ISBLANK(D34),IF(G34=1,VLOOKUP(E34,'Location Impute Tables'!$A$5:$J$9,10,0),VLOOKUP(E34,'Location Impute Tables'!$A$25:$J$29,10,0)),D34) -> New York | I34: =IF(ISBLANK(B34),IF(G34=1,VLOOKUP(H34,'Amount Impute Table'!$A$5:$F$9,MATCH(fraud_data!E34,'Amount Impute Table'!$B$4:$F$4,0)+1,FALSE),VLOOKUP(H34,'Amount Impute Table'!$A$16:$F$20,MATCH(E34,'Amount Impute Table'!$B$15:$F$15,0)+1,0)),B34) -> 904.33649
A35: 467 | B35: 286.43 | C35: 1759 | D35: New York | E35: Electronics | F35: 65 | G35: 0 | H35: =IF(ISBLANK(D35),IF(G35=1,VLOOKUP(E35,'Location Impute Tables'!$A$5:$J$9,10,0),VLOOKUP(E35,'Location Impute Tables'!$A$25:$J$29,10,0)),D35) -> New York | I35: =IF(ISBLANK(B35),IF(G35=1,VLOOKUP(H35,'Amount Impute Table'!$A$5:$F$9,MATCH(fraud_data!E35,'Amount Impute Table'!$B$4:$F$4,0)+1,FALSE),VLOOKUP(H35,'Amount Impute Table'!$A$16:$F$20,MATCH(E35,'Amount Impute Table'!$B$15:$F$15,0)+1,0)),B35) -> 286.43
A36: 466 | B36: 375.5 | C36: 75520 | D36: Chicago | E36: Groceries | F36: 58 | G36: 0 | H36: =IF(ISBLANK(D36),IF(G36=1,VLOOKUP(E36,'Location Impute Tables'!$A$5:$J$9,10,0),VLOOKUP(E36,'Location Impute Tables'!$A$25:$J$29,10,0)),D36) -> Chicago | I36: =IF(ISBLANK(B36),IF(G36=1,VLOOKUP(H36,'Amount Impute Table'!$A$5:$F$9,MATCH(fraud_data!E36,'Amount Impute Table'!$B$4:$F$4,0)+1,FALSE),VLOOKUP(H36,'Amount Impute Table'!$A$16:$F$20,MATCH(E36,'Amount Impute Table'!$B$15:$F$15,0)+1,0)),B36) -> 375.5
A37: 465 | B37: 962.21 | C37: 20806 | D37: Miami | E37: Electronics | F37: 19 | G37: 0 | H37: =IF(ISBLANK(D37),IF(G37=1,VLOOKUP(E37,'Location Impute Tables'!$A$5:$J$9,10,0),VLOOKUP(E37,'Location Impute Tables'!$A$25:$J$29,10,0)),D37) -> Miami | I37: =IF(ISBLANK(B37),IF(G37=1,VLOOKUP(H37,'Amount Impute Table'!$A$5:$F$9,MATCH(fraud_data!E37,'Amount Impute Table'!$B$4:$F$4,0)+1,FALSE),VLOOKUP(H37,'Amount Impute Table'!$A$16:$F$20,MATCH(E37,'Amount Impute Table'!$B$15:$F$15,0)+1,0)),B37) -> 962.21
A38: 464 | B38: 583.79 | C38: 62823 | D38: Los Angeles | E38: Travel | G38: 0 | H38: =IF(ISBLANK(D38),IF(G38=1,VLOOKUP(E38,'Location Impute Tables'!$A$5:$J$9,10,0),VLOOKUP(E38,'Location Impute Tables'!$A$25:$J$29,10,0)),D38) -> Los Angeles | I38: =IF(ISBLANK(B38),IF(G38=1,VLOOKUP(H38,'Amount Impute Table'!$A$5:$F$9,MATCH(fraud_data!E38,'Amount Impute Table'!$B$4:$F$4,0)+1,FALSE),VLOOKUP(H38,'Amount Impute Table'!$A$16:$F$20,MATCH(E38,'Amount Impute Table'!$B$15:$F$15,0)+1,0)),B38) -> 583.79
A39: 463 | B39: 746.3 | C39: 75452 | D39: Houston | E39: Travel | F39: 44 | G39: 0 | H39: =IF(ISBLANK(D39),IF(G39=1,VLOOKUP(E39,'Location Impute Tables'!$A$5:$J$9,10,0),VLOOKUP(E39,'Location Impute Tables'!$A$25:$J$29,10,0)),D39) -> Houston | I39: =IF(ISBLANK(B39),IF(G39=1,VLOOKUP(H39,'Amount Impute Table'!$A$5:$F$9,MATCH(fraud_data!E39,'Amount Impute Table'!$B$4:$F$4,0)+1,FALSE),VLOOKUP(H39,'Amount Impute Table'!$A$16:$F$20,MATCH(E39,'Amount Impute Table'!$B$15:$F$15,0)+1,0)),B39) -> 746.3
A40: 462 | B40: 649.56 | C40: 21566 | D40: Los Angeles | E40: Travel | F40: 56 | G40: 0 | H40: =IF(ISBLANK(D40),IF(G40=1,VLOOKUP(E40,'Location Impute Tables'!$A$5:$J$9,10,0),VLOOKUP(E40,'Location Impute Tables'!$A$25:$J$29,10,0)),D40) -> Los Angeles | I40: =IF(ISBLANK(B40),IF(G40=1,VLOOKUP(H40,'Amount Impute Table'!$A$5:$F$9,MATCH(fraud_data!E40,'Amount Impute Table'!$B$4:$F$4,0)+1,FALSE),VLOOKUP(H40,'Amount Impute Table'!$A$16:$F$20,MATCH(E40,'Amount Impute Table'!$B$15:$F$15,0)+1,0)),B40) -> 649.56
A41: 461 | B41: 118.41 | C41: 24917 | D41: New York | E41: Entertainment | F41: 63 | G41: 0 | H41: =IF(ISBLANK(D41),IF(G41=1,VLOOKUP(E41,'Location Impute Tables'!$A$5:$J$9,10,0),VLOOKUP(E41,'Location Impute Tables'!$A$25:$J$29,10,0)),D41) -> New York | I41: =IF(ISBLANK(B41),IF(G41=1,VLOOKUP(H41,'Amount Impute Table'!$A$5:$F$9,MATCH(fraud_data!E41,'Amount Impute Table'!$B$4:$F$4,0)+1,FALSE),VLOOKUP(H41,'Amount Impute Table'!$A$16:$F$20,MATCH(E41,'Amount Impute Table'!$B$15:$F$15,0)+1,0)),B41) -> 118.41
A42: 460 | B42: 119.7 | C42: 52853 | D42: Chicago | E42: Groceries | F42: 38 | G42: 0 | H42: =IF(ISBLANK(D42),IF(G42=1,VLOOKUP(E42,'Location Impute Tables'!$A$5:$J$9,10,0),VLOOKUP(E42,'Location Impute Tables'!$A$25:$J$29,10,0)),D42) -> Chicago | I42: =IF(ISBLANK(B42),IF(G42=1,VLOOKUP(H42,'Amount Impute Table'!$A$5:$F$9,MATCH(fraud_data!E42,'Amount Impute Table'!$B$4:$F$4,0)+1,FALSE),VLOOKUP(H42,'Amount Impute Table'!$A$16:$F$20,MATCH(E42,'Amount Impute Table'!$B$15:$F$15,0)+1,0)),B42) -> 119.7
A43: 459 | B43: 57.25 | C43: 49840 | D43: Chicago | E43: Entertainment | F43: 27 | G43: 0 | H43: =IF(ISBLANK(D43),IF(G43=1,VLOOKUP(E43,'Location Impute Tables'!$A$5:$J$9,10,0),VLOOKUP(E43,'Location Impute Tables'!$A$25:$J$29,10,0)),D43) -> Chicago | I43: =IF(ISBLANK(B43),IF(G43=1,VLOOKUP(H43,'Amount Impute Table'!$A$5:$F$9,MATCH(fraud_data!E43,'Amount Impute Table'!$B$4:$F$4,0)+1,FALSE),VLOOKUP(H43,'Amount Impute Table'!$A$16:$F$20,MATCH(E43,'Amount Impute Table'!$B$15:$F$15,0)+1,0)),B43) -> 57.25
...

Sheet Results
A1: IsFraud | B1: 1
A3: Average of Amount Imputed | B3: Column Labels
A4: Row Labels | B4: Clothing | C4: Electronics | D4: Entertainment | E4: Groceries | F4: Travel
A5: Chicago | B5: 216.61 | C5: 514.72 | D5: 31.47 | E5: 52.43 | F5: 892.15
A6: Houston | B6: 371.27 | C6: 860.87 | D6: 185.67 | E6: 0.00 | F6: 0.00
A7: Los Angeles | B7: 539.8 | C7: 974.42 | D7: 714.88 | E7: 94.58 | F7: 98.08
A8: Miami | B8: 162.47 | C8: 312.4 | D8: 586.19 | E8: 756.92 | F8: 225.05
A9: New York | B9: 360.83 | C9: 0.00 | D9: 939.56 | E9: 433.72 | F9: 0.00
